Workbook

Sheet HV
A5: Leistungsberechnung Hauptverteilung
A7: Installation / Verbraucher | B7: Stückzahl | C7: Einzel Leistung (kVA) | D7: Installierte Leistung (kVA) | E7: Gleichzeitigkeits- Faktor | F7: Gleichzeitige Leistung (kVA)
D10: =SUM(B10*C10) -> 0 | F10: =SUM(D10*E10) -> 0
A11: Wohnungstypen
A12: Wohnungsverteilung Typ 1 | C12: ='1'!F43 -> 1.75 | D12: =SUM(B12*C12) -> 0 | E12: 0.3 | F12: =SUM(D12*E12) -> 0
A13: Wohnungsverteilung Typ 2 | C13: ='2'!F43 -> 1.75 | D13: =SUM(B13*C13) -> 0 | E13: 0.3 | F13: =SUM(D13*E13) -> 0
A14: Wohnungsverteilung Typ 3 | C14: ='3'!F43 -> 1.75 | D14: =SUM(B14*C14) -> 0 | E14: 0.3 | F14: =SUM(D14*E14) -> 0
A15: Wohnungsverteilung Typ 4 | C15: ='4'!F43 -> 1.75 | D15: =SUM(B15*C15) -> 0 | E15: 0.3 | F15: =SUM(D15*E15) -> 0
A16: Wohnungsverteilung Typ 5 | C16: ='5'!F43 -> 1.75 | D16: =SUM(B16*C16) -> 0 | E16: 0.3 | F16: =SUM(D16*E16) -> 0
D17: =SUM(B17*C17) -> 0 | F17: =SUM(D17*E17) -> 0
D18: =SUM(B18*C18) -> 0 | F18: =SUM(D18*E18) -> 0
D19: =SUM(B19*C19) -> 0 | F19: =SUM(D19*E19) -> 0
D20: =SUM(B20*C20) -> 0 | F20: =SUM(D20*E20) -> 0
D21: =SUM(B21*C21) -> 0 | F21: =SUM(D21*E21) -> 0
D22: =SUM(B22*C22) -> 0 | F22: =SUM(D22*E22) -> 0
D23: =SUM(B23*C23) -> 0 | F23: =SUM(D23*E23) -> 0
D24: =SUM(B24*C24) -> 0 | F24: =SUM(D24*E24) -> 0
D25: =SUM(B25*C25) -> 0 | F25: =SUM(D25*E25) -> 0
D26: =SUM(B26*C26) -> 0 | F26: =SUM(D26*E26) -> 0
D27: =SUM(B27*C27) -> 0 | F27: =SUM(D27*E27) -> 0
D28: =SUM(B28*C28) -> 0 | F28: =SUM(D28*E28) -> 0
... D101: =SUM(B101*C101) -> 0 | F101: =SUM(D101*E101) -> 0
D102: =SUM(B102*C102) -> 0
D103: =SUM(B103*C103) -> 0 | F103: =SUM(D103*E103) -> 0
D104: =SUM(B104*C104) -> 0 | F104: =SUM(D104*E104) -> 0
D105: =SUM(B105*C105) -> 0 | F105: =SUM(D105*E105) -> 0
D106: =SUM(B106*C106) -> 0 | F106: =SUM(D106*E106) -> 0
D107: =SUM(B107*C107) -> 0 | F107: =SUM(D107*E107) -> 0
D108: =SUM(B108*C108) -> 0 | F108: =SUM(D108*E108) -> 0
D109: =SUM(B109*C109) -> 0 | F109: =SUM(D109*E109) -> 0
D110: =SUM(B110*C110) -> 0 | F110: =SUM(D110*E110) -> 0
D111: =SUM(B111*C111) -> 0 | F111: =SUM(D111*E111) -> 0
D112: =SUM(B112*C112) -> 0 | F112: =SUM(D112*E112) -> 0
D113: =SUM(B113*C113) -> 0 | F113: =SUM(D113*E113) -> 0
D114: =SUM(B114*C114) -> 0 | F114: =SUM(D114*E114) -> 0
... D132: =SUM(B132*C132) -> 0 | F132: =SUM(D132*E132) -> 0
F133: =SUM(D133*E133) -> 0
A135: Zwischentotal | D135: =SUM(D15:D133) -> 0 | E135: kVA | F135: =SUM(F10:F133) -> 0
A137: Nennstrom ohne GF über alles | E137: A | F137: =SUM(F135/0.6928) -> 0
A139: GF über alles | E139: GF | F139: 0.7
...

Sheet 1
A5: Leistungsberechnung Typ 1
A7: Installation / Verbraucher | B7: Stückzahl | C7: Einzel Leistung (kVA) | D7: Installierte Leistung (kVA) | E7: Gleichzeitigkeits- Faktor | F7: Gleichzeitige Leistung (kVA)
D10: =SUM(B10*C10) -> 0 | F10: =SUM(D10*E10) -> 0
A11: Wohnungsverteilung Typ 1 | D11: =SUM(B11*C11) -> 0 | F11: =SUM(D11*E11) -> 0
D12: =SUM(B12*C12) -> 0 | F12: =SUM(D12*E12) -> 0
D13: =SUM(B13*C13) -> 0 | F13: =SUM(D13*E13) -> 0
D14: =SUM(B14*C14) -> 0 | F14: =SUM(D14*E14) -> 0
D15: =SUM(B15*C15) -> 0 | F15: =SUM(D15*E15) -> 0
D16: =SUM(B16*C16) -> 0 | F16: =SUM(D16*E16) -> 0
D17: =SUM(B17*C17) -> 0 | F17: =SUM(D17*E17) -> 0
D18: =SUM(B18*C18) -> 0 | F18: =SUM(D18*E18) -> 0
D19: =SUM(B19*C19) -> 0 | F19: =SUM(D19*E19) -> 0
D20: =SUM(B20*C20) -> 0 | F20: =SUM(D20*E20) -> 0
D21: =SUM(B21*C21) -> 0 | F21: =SUM(D21*E21) -> 0
D22: =SUM(B22*C22) -> 0 | F22: =SUM(D22*E22) -> 0
D23: =SUM(B23*C23) -> 0 | F23: =SUM(D23*E23) -> 0
... D33: =SUM(B33*C33) -> 0 | F33: =SUM(D33*E33) -> 0
A34: Diverse / Ausbaureserve | D34: 5 | E34: 0.5 | F34: =SUM(D34*E34) -> 2.5
A36: Zwischentotal | D36: =SUM(D12:D34) -> 5 | E36: kVA | F36: =SUM(F10:F34) -> 2.5
A38: Nennstrom ohne GF über alles | E38: A | F38: =SUM(F36/0.6928) -> 3.608545
A40: GF über alles | E40: GF | F40: 0.7
A43: Scheinleistung gleichzeitig | E43: kVA | F43: =SUM(F36*F40) -> 1.75
A44: Nennstrom gleichzeitig | E44: A | F44: =SUM(F43/0.6928) -> 2.5259815
A45: Zuleitungsquerschnitt | E45: mm2 | F45: 6mm²
A46: Anschluss- / Bezügersicherung | E46: A | F46: 25A
A47: Nennleistung Transformator | E47: kVA

Sheet 2
A5: Leistungsberechnung Typ 2
A7: Installation / Verbraucher | B7: Stückzahl | C7: Einzel Leistung (kVA) | D7: Installierte Leistung (kVA) | E7: Gleichzeitigkeits- Faktor | F7: Gleichzeitige Leistung (kVA)
D10: =SUM(B10*C10) -> 0 | F10: =SUM(D10*E10) -> 0
A11: Wohnungsverteilung Typ 2 | D11: =SUM(B11*C11) -> 0 | F11: =SUM(D11*E11) -> 0
D12: =SUM(B12*C12) -> 0 | F12: =SUM(D12*E12) -> 0
D13: =SUM(B13*C13) -> 0 | F13: =SUM(D13*E13) -> 0
D14: =SUM(B14*C14) -> 0 | F14: =SUM(D14*E14) -> 0
D15: =SUM(B15*C15) -> 0 | F15: =SUM(D15*E15) -> 0
D16: =SUM(B16*C16) -> 0 | F16: =SUM(D16*E16) -> 0
D17: =SUM(B17*C17) -> 0 | F17: =SUM(D17*E17) -> 0
D18: =SUM(B18*C18) -> 0 | F18: =SUM(D18*E18) -> 0
D19: =SUM(B19*C19) -> 0 | F19: =SUM(D19*E19) -> 0
D20: =SUM(B20*C20) -> 0 | F20: =SUM(D20*E20) -> 0
D21: =SUM(B21*C21) -> 0 | F21: =SUM(D21*E21) -> 0
D22: =SUM(B22*C22) -> 0 | F22: =SUM(D22*E22) -> 0
D23: =SUM(B23*C23) -> 0 | F23: =SUM(D23*E23) -> 0
... D33: =SUM(B33*C33) -> 0 | F33: =SUM(D33*E33) -> 0
A34: Diverse / Ausbaureserve | D34: 5 | E34: 0.5 | F34: =SUM(D34*E34) -> 2.5
A36: Zwischentotal | D36: =SUM(D12:D34) -> 5 | E36: kVA | F36: =SUM(F10:F34) -> 2.5
A38: Nennstrom ohne GF über alles | E38: A | F38: =SUM(F36/0.6928) -> 3.608545
A40: GF über alles | E40: GF | F40: 0.7
A43: Scheinleistung gleichzeitig | E43: kVA | F43: =SUM(F36*F40) -> 1.75
A44: Nennstrom gleichzeitig | E44: A | F44: =SUM(F43/0.6928) -> 2.5259815
A45: Zuleitungsquerschnitt | E45: mm2 | F45: 6mm²
A46: Anschluss- / Bezügersicherung | E46: A | F46: 25A
A47: Nennleistung Transformator | E47: kVA

Sheet 3
A5: Leistungsberechnung Typ 3
A7: Installation / Verbraucher | B7: Stückzahl | C7: Einzel Leistung (kVA) | D7: Installierte Leistung (kVA) | E7: Gleichzeitigkeits- Faktor | F7: Gleichzeitige Leistung (kVA)
D10: =SUM(B10*C10) -> 0 | F10: =SUM(D10*E10) -> 0
A11: Wohnungsverteilung Typ 3 | D11: =SUM(B11*C11) -> 0 | F11: =SUM(D11*E11) -> 0
D12: =SUM(B12*C12) -> 0 | F12: =SUM(D12*E12) -> 0
D13: =SUM(B13*C13) -> 0 | F13: =SUM(D13*E13) -> 0
D14: =SUM(B14*C14) -> 0 | F14: =SUM(D14*E14) -> 0
D15: =SUM(B15*C15) -> 0 | F15: =SUM(D15*E15) -> 0
D16: =SUM(B16*C16) -> 0 | F16: =SUM(D16*E16) -> 0
D17: =SUM(B17*C17) -> 0 | F17: =SUM(D17*E17) -> 0
D18: =SUM(B18*C18) -> 0 | F18: =SUM(D18*E18) -> 0
D19: =SUM(B19*C19) -> 0 | F19: =SUM(D19*E19) -> 0
D20: =SUM(B20*C20) -> 0 | F20: =SUM(D20*E20) -> 0
D21: =SUM(B21*C21) -> 0 | F21: =SUM(D21*E21) -> 0
D22: =SUM(B22*C22) -> 0 | F22: =SUM(D22*E22) -> 0
D23: =SUM(B23*C23) -> 0 | F23: =SUM(D23*E23) -> 0
... D33: =SUM(B33*C33) -> 0 | F33: =SUM(D33*E33) -> 0
A34: Diverse / Ausbaureserve | D34: 5 | E34: 0.5 | F34: =SUM(D34*E34) -> 2.5
A36: Zwischentotal | D36: =SUM(D12:D34) -> 5 | E36: kVA | F36: =SUM(F10:F34) -> 2.5
A38: Nennstrom ohne GF über alles | E38: A | F38: =SUM(F36/0.6928) -> 3.608545
A40: GF über alles | E40: GF | F40: 0.7
A43: Scheinleistung gleichzeitig | E43: kVA | F43: =SUM(F36*F40) -> 1.75
A44: Nennstrom gleichzeitig | E44: A | F44: =SUM(F43/0.6928) -> 2.5259815
A45: Zuleitungsquerschnitt | E45: mm2 | F45: 6mm²
A46: Anschluss- / Bezügersicherung | E46: A | F46: 25A
A47: Nennleistung Transformator | E47: kVA

Sheet 4
A5: Leistungsberechnung Typ 4
A7: Installation / Verbraucher | B7: Stückzahl | C7: Einzel Leistung (kVA) | D7: Installierte Leistung (kVA) | E7: Gleichzeitigkeits- Faktor | F7: Gleichzeitige Leistung (kVA)
D10: =SUM(B10*C10) -> 0 | F10: =SUM(D10*E10) -> 0
A11: Wohnungsverteilung Typ 4 | D11: =SUM(B11*C11) -> 0 | F11: =SUM(D11*E11) -> 0
D12: =SUM(B12*C12) -> 0 | F12: =SUM(D12*E12) -> 0
D13: =SUM(B13*C13) -> 0 | F13: =SUM(D13*E13) -> 0
D14: =SUM(B14*C14) -> 0 | F14: =SUM(D14*E14) -> 0
D15: =SUM(B15*C15) -> 0 | F15: =SUM(D15*E15) -> 0
D16: =SUM(B16*C16) -> 0 | F16: =SUM(D16*E16) -> 0
D17: =SUM(B17*C17) -> 0 | F17: =SUM(D17*E17) -> 0
D18: =SUM(B18*C18) -> 0 | F18: =SUM(D18*E18) -> 0
D19: =SUM(B19*C19) -> 0 | F19: =SUM(D19*E19) -> 0
D20: =SUM(B20*C20) -> 0 | F20: =SUM(D20*E20) -> 0
D21: =SUM(B21*C21) -> 0 | F21: =SUM(D21*E21) -> 0
D22: =SUM(B22*C22) -> 0 | F22: =SUM(D22*E22) -> 0
D23: =SUM(B23*C23) -> 0 | F23: =SUM(D23*E23) -> 0
... D33: =SUM(B33*C33) -> 0 | F33: =SUM(D33*E33) -> 0
A34: Diverse / Ausbaureserve | D34: 5 | E34: 0.5 | F34: =SUM(D34*E34) -> 2.5
A36: Zwischentotal | D36: =SUM(D12:D34) -> 5 | E36: kVA | F36: =SUM(F10:F34) -> 2.5
A38: Nennstrom ohne GF über alles | E38: A | F38: =SUM(F36/0.6928) -> 3.608545
A40: GF über alles | E40: GF | F40: 0.7
A43: Scheinleistung gleichzeitig | E43: kVA | F43: =SUM(F36*F40) -> 1.75
A44: Nennstrom gleichzeitig | E44: A | F44: =SUM(F43/0.6928) -> 2.5259815
A45: Zuleitungsquerschnitt | E45: mm2 | F45: 6mm²
A46: Anschluss- / Bezügersicherung | E46: A | F46: 25A
A47: Nennleistung Transformator | E47: kVA

Sheet 5
A5: Leistungsberechnung Typ 5
A7: Installation / Verbraucher | B7: Stückzahl | C7: Einzel Leistung (kVA) | D7: Installierte Leistung (kVA) | E7: Gleichzeitigkeits- Faktor | F7: Gleichzeitige Leistung (kVA)
D10: =SUM(B10*C10) -> 0 | F10: =SUM(D10*E10) -> 0
A11: Wohnungsverteilung Typ 5 | D11: =SUM(B11*C11) -> 0 | F11: =SUM(D11*E11) -> 0
D12: =SUM(B12*C12) -> 0 | F12: =SUM(D12*E12) -> 0
D13: =SUM(B13*C13) -> 0 | F13: =SUM(D13*E13) -> 0
D14: =SUM(B14*C14) -> 0 | F14: =SUM(D14*E14) -> 0
D15: =SUM(B15*C15) -> 0 | F15: =SUM(D15*E15) -> 0
D16: =SUM(B16*C16) -> 0 | F16: =SUM(D16*E16) -> 0
D17: =SUM(B17*C17) -> 0 | F17: =SUM(D17*E17) -> 0
D18: =SUM(B18*C18) -> 0 | F18: =SUM(D18*E18) -> 0
D19: =SUM(B19*C19) -> 0 | F19: =SUM(D19*E19) -> 0
D20: =SUM(B20*C20) -> 0 | F20: =SUM(D20*E20) -> 0
D21: =SUM(B21*C21) -> 0 | F21: =SUM(D21*E21) -> 0
D22: =SUM(B22*C22) -> 0 | F22: =SUM(D22*E22) -> 0
D23: =SUM(B23*C23) -> 0 | F23: =SUM(D23*E23) -> 0
... D33: =SUM(B33*C33) -> 0 | F33: =SUM(D33*E33) -> 0
A34: Diverse / Ausbaureserve | D34: 5 | E34: 0.5 | F34: =SUM(D34*E34) -> 2.5
A36: Zwischentotal | D36: =SUM(D12:D34) -> 5 | E36: kVA | F36: =SUM(F10:F34) -> 2.5
A38: Nennstrom ohne GF über alles | E38: A | F38: =SUM(F36/0.6928) -> 3.608545
A40: GF über alles | E40: GF | F40: 0.7
A43: Scheinleistung gleichzeitig | E43: kVA | F43: =SUM(F36*F40) -> 1.75
A44: Nennstrom gleichzeitig | E44: A | F44: =SUM(F43/0.6928) -> 2.5259815
A45: Zuleitungsquerschnitt | E45: mm2 | F45: 6mm²
A46: Anschluss- / Bezügersicherung | E46: A | F46: 25A
A47: Nennleistung Transformator | E47: kVA
